Workbook

Sheet Leia-me
A1: NOEMA: economia unitária (2026-10-19)
A3: Fontes: docs/pricing/PRICING_AUDIT.md, market-2026-10-19.md, usage-audit-2026-10-19.md.
A4: Regenerar: uv run --with openpyxl python scripts/pricing/build_unit_economics.py
A6: Legenda:
A7: entrada editável | B7: fonte azul, fundo amarelo: edite e tudo recalcula
A8: resultado-chave | B8: fundo verde: saída principal da aba
A9: auditoria | B9: cinza itálico: valor da auditoria, só para comparar
A11: Resultados-chave
A12: Métrica | B12: Conservador | C12: Otimizado
A13: Custo por troca (US¢) | B13: ='Custo por operação'!$C$22 | C13: ='Custo por operação'!$D$22
A14: Aula de 10 trocas (US¢) | B14: ='Custo por operação'!$D$55 | C14: ='Custo por operação'!$E$55
A15: Margem bruta Plus | B15: ='Planos'!$D$27 | C15: ='Planos'!$D$28
A16: Margem bruta Pro | B16: ='Planos'!$E$27 | C16: ='Planos'!$E$28
A17: Margem bruta no mix 80/20 | B17: ='Planos'!$D$29 | C17: ='Planos'!$D$30
A18: LTV em lucro bruto (R$) | B18: ='CAC'!$C$8
A19: CAC-alvo (R$) | B19: ='CAC'!$C$9

Sheet Premissas
A1: Premissas
A2: Células azuis sobre fundo amarelo são entradas. Edite-as; o resto recalcula.
B4: Premissa | C4: Valor | D4: Fonte / nota
B5: Câmbio de planejamento (R$ por US$) | C5: 5.65 | D5: PRICING_AUDIT: PTAX + ~12% de buffer
B6: PTAX venda em 19/10/2026 | C6: 5.0564 | D6: market-2026-10-19 §3 (BCB)
B7: Imposto sobre a receita | C7: 0.06 | D7: PRICING_AUDIT, risco 6: regime ainda indefinido
B8: Gateway: cartão (Stripe BR) | C8: 0.0399 | D8: market §4: 3,99% + R$ 0,39
B9: Gateway: fixo por cobrança (R$) | C9: 0.39 | D9: market §4
B10: Gateway: Stripe Billing (% do volume) | C10: 0.007 | D10: market §4
B11: Reembolsos (% da receita) | C11: 0.02 | D11: PRICING_AUDIT, tetos de CAC
B12: Churn mensal | C12: 0.1 | D12: PRICING_AUDIT, caso base
B13: Conversão cadastro → pagante | C13: 0.03 | D13: PRICING_AUDIT (instável até dados reais)
B14: LTV:CAC alvo | C14: 3 | D14: PRICING_AUDIT
B15: Payback do CAC (meses) | C15: 3 | D15: PRICING_AUDIT
B16: Margem bruta do caso base (para o CAC) | C16: 0.7 | D16: PRICING_AUDIT: 'alvo realista pós-otimização'
... B22: Desconto batch (ingestão de PDF) | C22: 0.5 | D22: market §1: batch = 50% nos dois provedores
B23: Deduções sobre a receita (imposto + reembolsos + gateway %) | C23: ='Premissas'!$C$7+'Premissas'!$C$11+'Premissas'!$C$8+'Premissas'!$C$10 | D23: Receita líquida = preço × (1 − deduções) − fixo do gateway
B24: Verificação: mix Plus + Pro | C24: ='Premissas'!$C$17+'Premissas'!$C$18 | D24: Deve dar 100%

Sheet Preços API
A1: Preços oficiais das APIs (US$ por 1M tokens)
A2: Consultados em 2026-10-19 nas páginas dos provedores (market-2026-10-19.md §1). Batch = 50% de desconto; residência de dados = +10%.
A4: Provedor | B4: Modelo | C4: Input | D4: Cache (leitura) | E4: Cache (escrita, 5 min) | F4: Output | G4: Fonte | H4: Data | I4: Observação
A5: Anthropic | B5: Haiku 5.5 | C5: 0.1 | D5: 0.01 | E5: 0.125 | F5: 0.5 | G5: https://platform.claude.com/docs/en/about-claude/pricing | H5: 2026-10-19 | I5: Prompt até 100K; acima: 0,50 / 0,05 / 2,50
A6: Anthropic | B6: Sonnet 5.5 | C6: 2 | D6: 0.1 | E6: 2.5 | F6: 10 | G6: https://platform.claude.com/docs/en/about-claude/pricing | H6: 2026-10-19 | I6: Leitura de cache 0,05× o input
A7: Anthropic | B7: Opus 5.5 | C7: 4 | D7: 0.2 | E7: 5 | F7: 20 | G7: https://platform.claude.com/docs/en/about-claude/pricing | H7: 2026-10-19 | I7: Leitura de cache 0,05× o input
A8: OpenAI | B8: GPT-5.6 Luna | C8: 0.2 | D8: 0.02 | E8: 0.25 | F8: 1.2 | G8: https://developers.openai.com/api/docs/pricing | H8: 2026-10-19 | I8: Substituto do gpt-4.1-nano
A9: OpenAI | B9: GPT-5.6 Terra | C9: 2 | D9: 0.2 | E9: 2.5 | F9: 12 | G9: https://developers.openai.com/api/docs/pricing | H9: 2026-10-19
A10: OpenAI | B10: GPT-5.6 Sol | C10: 4 | D10: 0.4 | E10: 5 | F10: 20 | G10: https://developers.openai.com/api/docs/pricing | H10: 2026-10-19 | I10: Acima de 272K de input: 2× input, 1,5× output
A11: OpenAI | B11: gpt-4.1 | C11: 2 | D11: 0.5 | E11: 2 | F11: 8 | G11: https://developers.openai.com/api/docs/pricing | H11: 2026-10-19 | I11: Sai em 14/01/2027. Sem sobretaxa de escrita de cache
A12: OpenAI | B12: gpt-4.1-mini | C12: 0.4 | D12: 0.1 | E12: 0.4 | F12: 1.6 | G12: https://developers.openai.com/api/docs/pricing | H12: 2026-10-19 | I12: Sai em 14/01/2027. Sem sobretaxa de escrita de cache
A13: OpenAI | B13: text-embedding-3-small | C13: 0.02 | D13: 0 | E13: 0 | F13: 0 | G13: https://developers.openai.com/api/docs/pricing | H13: 2026-10-19 | I13: Só input

Sheet Custo por operação
A1: Custo por operação (US¢ por chamada, preço de lista)
A2: custo = (input novo × p_in + cache × p_cache + escrita × p_escrita + output × p_out) ÷ 1e6 × 100
B4: Operação | C4: Input novo (tok) | D4: Input em cache (tok) | E4: Escrita de cache (tok) | F4: Output (tok) | G4: Haiku 5.5 | H4: Sonnet 5.5 | I4: Opus 5.5 | J4: GPT-5.6 Luna | K4: GPT-5.6 Terra | L4: GPT-5.6 Sol | M4: gpt-4.1 | N4: gpt-4.1-mini | O4: Fonte
B5: Troca com o Mino (chamada de ensino) | C5: 800 | D5: 4500 | E5: 0 | F5: 500 | G5: =($C5*'Preços API'!$C$5+$D5*'Preços API'!$D$5+$E5*'Preços API'!$E$5+$F5*'Preços API'!$F$5)/1000000*100 | H5: =($C5*'Preços API'!$C$6+$D5*'Preços API'!$D$6+$E5*'Preços API'!$E$6+$F5*'Preços API'!$F$6)/1000000*100 | I5: =($C5*'Preços API'!$C$7+$D5*'Preços API'!$D$7+$E5*'Preços API'!$E$7+$F5*'Preços API'!$F$7)/1000000*100 | J5: =($C5*'Preços API'!$C$8+$D5*'Preços API'!$D$8+$E5*'Preços API'!$E$8+$F5*'Preços API'!$F$8)/1000000*100 | K5: =($C5*'Preços API'!$C$9+$D5*'Preços API'!$D$9+$E5*'Preços API'!$E$9+$F5*'Preços API'!$F$9)/1000000*100 | L5: =($C5*'Preços API'!$C$10+$D5*'Preços API'!$D$10+$E5*'Preços API'!$E$10+$F5*'Preços API'!$F$10)/1000000*100 | M5: =($C5*'Preços API'!$C$11+$D5*'Preços API'!$D$11+$E5*'Preços API'!$E$11+$F5*'Preços API'!$F$11)/1000000*100 | N5: =($C5*'Preços API'!$C$12+$D5*'Preços API'!$D$12+$E5*'Preços API'!$E$12+$F5*'Preços API'!$F$12)/1000000*100 | O5: PRICING_AUDIT: 800 novos, 4.500 em cache. Saída: ver nota abaixo da tabela
B6: Classificador de rota | C6: 765 | D6: 0 | E6: 0 | F6: 15 | G6: =($C6*'Preços API'!$C$5+$D6*'Preços API'!$D$5+$E6*'Preços API'!$E$5+$F6*'Preços API'!$F$5)/1000000*100 | H6: =($C6*'Preços API'!$C$6+$D6*'Preços API'!$D$6+$E6*'Preços API'!$E$6+$F6*'Preços API'!$F$6)/1000000*100 | I6: =($C6*'Preços API'!$C$7+$D6*'Preços API'!$D$7+$E6*'Preços API'!$E$7+$F6*'Preços API'!$F$7)/1000000*100 | J6: =($C6*'Preços API'!$C$8+$D6*'Preços API'!$D$8+$E6*'Preços API'!$E$8+$F6*'Preços API'!$F$8)/1000000*100 | K6: =($C6*'Preços API'!$C$9+$D6*'Preços API'!$D$9+$E6*'Preços API'!$E$9+$F6*'Preços API'!$F$9)/1000000*100 | L6: =($C6*'Preços API'!$C$10+$D6*'Preços API'!$D$10+$E6*'Preços API'!$E$10+$F6*'Preços API'!$F$10)/1000000*100 | M6: =($C6*'Preços API'!$C$11+$D6*'Preços API'!$D$11+$E6*'Preços API'!$E$11+$F6*'Preços API'!$F$11)/1000000*100 | N6: =($C6*'Preços API'!$C$12+$D6*'Preços API'!$D$12+$E6*'Preços API'!$E$12+$F6*'Preços API'!$F$12)/1000000*100 | O6: usage-audit C1
B7: Parse do objetivo | C7: 350 | D7: 0 | E7: 0 | F7: 120 | G7: =($C7*'Preços API'!$C$5+$D7*'Preços API'!$D$5+$E7*'Preços API'!$E$5+$F7*'Preços API'!$F$5)/1000000*100 | H7: =($C7*'Preços API'!$C$6+$D7*'Preços API'!$D$6+$E7*'Preços API'!$E$6+$F7*'Preços API'!$F$6)/1000000*100 | I7: =($C7*'Preços API'!$C$7+$D7*'Preços API'!$D$7+$E7*'Preços API'!$E$7+$F7*'Preços API'!$F$7)/1000000*100 | J7: =($C7*'Preços API'!$C$8+$D7*'Preços API'!$D$8+$E7*'Preços API'!$E$8+$F7*'Preços API'!$F$8)/1000000*100 | K7: =($C7*'Preços API'!$C$9+$D7*'Preços API'!$D$9+$E7*'Preços API'!$E$9+$F7*'Preços API'!$F$9)/1000000*100 | L7: =($C7*'Preços API'!$C$10+$D7*'Preços API'!$D$10+$E7*'Preços API'!$E$10+$F7*'Preços API'!$F$10)/1000000*100 | M7: =($C7*'Preços API'!$C$11+$D7*'Preços API'!$D$11+$E7*'Preços API'!$E$11+$F7*'Preços API'!$F$11)/1000000*100 | N7: =($C7*'Preços API'!$C$12+$D7*'Preços API'!$D$12+$E7*'Preços API'!$E$12+$F7*'Preços API'!$F$12)/1000000*100 | O7: usage-audit C2
B8: Currículo | C8: 550 | D8: 0 | E8: 0 | F8: 1200 | G8: =($C8*'Preços API'!$C$5+$D8*'Preços API'!$D$5+$E8*'Preços API'!$E$5+$F8*'Preços API'!$F$5)/1000000*100 | H8: =($C8*'Preços API'!$C$6+$D8*'Preços API'!$D$6+$E8*'Preços API'!$E$6+$F8*'Preços API'!$F$6)/1000000*100 | I8: =($C8*'Preços API'!$C$7+$D8*'Preços API'!$D$7+$E8*'Preços API'!$E$7+$F8*'Preços API'!$F$7)/1000000*100 | J8: =($C8*'Preços API'!$C$8+$D8*'Preços API'!$D$8+$E8*'Preços API'!$E$8+$F8*'Preços API'!$F$8)/1000000*100 | K8: =($C8*'Preços API'!$C$9+$D8*'Preços API'!$D$9+$E8*'Preços API'!$E$9+$F8*'Preços API'!$F$9)/1000000*100 | L8: =($C8*'Preços API'!$C$10+$D8*'Preços API'!$D$10+$E8*'Preços API'!$E$10+$F8*'Preços API'!$F$10)/1000000*100 | M8: =($C8*'Preços API'!$C$11+$D8*'Preços API'!$D$11+$E8*'Preços API'!$E$11+$F8*'Preços API'!$F$11)/1000000*100 | N8: =($C8*'Preços API'!$C$12+$D8*'Preços API'!$D$12+$E8*'Preços API'!$E$12+$F8*'Preços API'!$F$12)/1000000*100 | O8: usage-audit C2
B9: Quiz de checkpoint (assessment) | C9: 2400 | D9: 0 | E9: 0 | F9: 1100 | G9: =($C9*'Preços API'!$C$5+$D9*'Preços API'!$D$5+$E9*'Preços API'!$E$5+$F9*'Preços API'!$F$5)/1000000*100 | H9: =($C9*'Preços API'!$C$6+$D9*'Preços API'!$D$6+$E9*'Preços API'!$E$6+$F9*'Preços API'!$F$6)/1000000*100 | I9: =($C9*'Preços API'!$C$7+$D9*'Preços API'!$D$7+$E9*'Preços API'!$E$7+$F9*'Preços API'!$F$7)/1000000*100 | J9: =($C9*'Preços API'!$C$8+$D9*'Preços API'!$D$8+$E9*'Preços API'!$E$8+$F9*'Preços API'!$F$8)/1000000*100 | K9: =($C9*'Preços API'!$C$9+$D9*'Preços API'!$D$9+$E9*'Preços API'!$E$9+$F9*'Preços API'!$F$9)/1000000*100 | L9: =($C9*'Preços API'!$C$10+$D9*'Preços API'!$D$10+$E9*'Preços API'!$E$10+$F9*'Preços API'!$F$10)/1000000*100 | M9: =($C9*'Preços API'!$C$11+$D9*'Preços API'!$D$11+$E9*'Preços API'!$E$11+$F9*'Preços API'!$F$11)/1000000*100 | N9: =($C9*'Preços API'!$C$12+$D9*'Preços API'!$D$12+$E9*'Preços API'!$E$12+$F9*'Preços API'!$F$12)/1000000*100 | O9: usage-audit C2
B10: Lote de flashcards | C10: 1800 | D10: 0 | E10: 0 | F10: 300 | G10: =($C10*'Preços API'!$C$5+$D10*'Preços API'!$D$5+$E10*'Preços API'!$E$5+$F10*'Preços API'!$F$5)/1000000*100 | H10: =($C10*'Preços API'!$C$6+$D10*'Preços API'!$D$6+$E10*'Preços API'!$E$6+$F10*'Preços API'!$F$6)/1000000*100 | I10: =($C10*'Preços API'!$C$7+$D10*'Preços API'!$D$7+$E10*'Preços API'!$E$7+$F10*'Preços API'!$F$7)/1000000*100 | J10: =($C10*'Preços API'!$C$8+$D10*'Preços API'!$D$8+$E10*'Preços API'!$E$8+$F10*'Preços API'!$F$8)/1000000*100 | K10: =($C10*'Preços API'!$C$9+$D10*'Preços API'!$D$9+$E10*'Preços API'!$E$9+$F10*'Preços API'!$F$9)/1000000*100 | L10: =($C10*'Preços API'!$C$10+$D10*'Preços API'!$D$10+$E10*'Preços API'!$E$10+$F10*'Preços API'!$F$10)/1000000*100 | M10: =($C10*'Preços API'!$C$11+$D10*'Preços API'!$D$11+$E10*'Preços API'!$E$11+$F10*'Preços API'!$F$11)/1000000*100 | N10: =($C10*'Preços API'!$C$12+$D10*'Preços API'!$D$12+$E10*'Preços API'!$E$12+$F10*'Preços API'!$F$12)/1000000*100 | O10: usage-audit C2
B11: Compactação de memória | C11: 5500 | D11: 0 | E11: 0 | F11: 450 | G11: =($C11*'Preços API'!$C$5+$D11*'Preços API'!$D$5+$E11*'Preços API'!$E$5+$F11*'Preços API'!$F$5)/1000000*100 | H11: =($C11*'Preços API'!$C$6+$D11*'Preços API'!$D$6+$E11*'Preços API'!$E$6+$F11*'Preços API'!$F$6)/1000000*100 | I11: =($C11*'Preços API'!$C$7+$D11*'Preços API'!$D$7+$E11*'Preços API'!$E$7+$F11*'Preços API'!$F$7)/1000000*100 | J11: =($C11*'Preços API'!$C$8+$D11*'Preços API'!$D$8+$E11*'Preços API'!$E$8+$F11*'Preços API'!$F$8)/1000000*100 | K11: =($C11*'Preços API'!$C$9+$D11*'Preços API'!$D$9+$E11*'Preços API'!$E$9+$F11*'Preços API'!$F$9)/1000000*100 | L11: =($C11*'Preços API'!$C$10+$D11*'Preços API'!$D$10+$E11*'Preços API'!$E$10+$F11*'Preços API'!$F$10)/1000000*100 | M11: =($C11*'Preços API'!$C$11+$D11*'Preços API'!$D$11+$E11*'Preços API'!$E$11+$F11*'Preços API'!$F$11)/1000000*100 | N11: =($C11*'Preços API'!$C$12+$D11*'Preços API'!$D$12+$E11*'Preços API'!$E$12+$F11*'Preços API'!$F$12)/1000000*100 | O11: usage-audit C2
B12: Extração de conceitos (lote de 5 chunks) | C12: 3000 | D12: 0 | E12: 0 | F12: 400 | G12: =($C12*'Preços API'!$C$5+$D12*'Preços API'!$D$5+$E12*'Preços API'!$E$5+$F12*'Preços API'!$F$5)/1000000*100 | H12: =($C12*'Preços API'!$C$6+$D12*'Preços API'!$D$6+$E12*'Preços API'!$E$6+$F12*'Preços API'!$F$6)/1000000*100 | I12: =($C12*'Preços API'!$C$7+$D12*'Preços API'!$D$7+$E12*'Preços API'!$E$7+$F12*'Preços API'!$F$7)/1000000*100 | J12: =($C12*'Preços API'!$C$8+$D12*'Preços API'!$D$8+$E12*'Preços API'!$E$8+$F12*'Preços API'!$F$8)/1000000*100 | K12: =($C12*'Preços API'!$C$9+$D12*'Preços API'!$D$9+$E12*'Preços API'!$E$9+$F12*'Preços API'!$F$9)/1000000*100 | L12: =($C12*'Preços API'!$C$10+$D12*'Preços API'!$D$10+$E12*'Preços API'!$E$10+$F12*'Preços API'!$F$10)/1000000*100 | M12: =($C12*'Preços API'!$C$11+$D12*'Preços API'!$D$11+$E12*'Preços API'!$E$11+$F12*'Preços API'!$F$11)/1000000*100 | N12: =($C12*'Preços API'!$C$12+$D12*'Preços API'!$D$12+$E12*'Preços API'!$E$12+$F12*'Preços API'!$F$12)/1000000*100 | O12: usage-audit C5
B14: Saída da troca: a auditoria escreve 'saída média de 300', mas os seus resultados (0,74¢ / 0,34¢ por troca; R$ 104,56 / R$ 47,99 para 2.500 trocas) só fecham com 500 tokens de saída (ou 1.800 de input novo). A planilha usa 500 para reproduzir a auditoria; com 300 a troca conservadora cai para ~0,53¢.
B16: Roteamento da troca com o Mino
B17: Modelo | C17: Conservador | D17: Otimizado | E17: Custo da troca no modelo (US¢)
B18: Haiku 5.5 | C18: 0 | D18: 0.6 | E18: =G5 | F18: PRICING_AUDIT, premissas das colunas: conservador = Sonnet 95% + Opus 5%;
B19: Sonnet 5.5 | C19: 0.95 | D19: 0.35 | E19: =H5 | F19: otimizado = Haiku 60% + Sonnet 35% + Opus 5% (se o Haiku passar no eval).
B20: Opus 5.5 | C20: 0.05 | D20: 0.05 | E20: =I5
B21: Soma (deve dar 100%) | C21: =SUM(C18:C20) | D21: =SUM(D18:D20)
B22: Custo médio por troca (US¢) | C22: =SUMPRODUCT(C18:C20,$E$18:$E$20) | D22: =SUMPRODUCT(D18:D20,$E$18:$E$20) | E22: 0.74 | F22: 0.34 | G22: ← auditoria: 0,74¢ / 0,34¢
B23: Custo médio por troca (R$) | C23: =C22/100*'Premissas'!$C$5 | D23: =D22/100*'Premissas'!$C$5
B24: Troca + classificador de rota (US¢, informativo) | C24: =C22+'Premissas'!$C$21*G6 | D24: =D22+'Premissas'!$C$21*G6 | E24: A auditoria não inclui a rota no custo da troca; ela entra nas chamadas laterais da aula.
B26: Chamadas laterais: modelo por cenário
B27: Operação | C27: Modelo (conservador) | D27: Custo conservador (US¢) | E27: Modelo (otimizado) | F27: Custo otimizado (US¢) | G27: Auditoria cons. (US¢) | H27: Auditoria otim. (US¢)
B28: Classificador de rota | C28: Haiku 5.5 | D28: =INDEX($G$6:$N$6,1,MATCH($C28,$G$4:$N$4,0)) | E28: Haiku 5.5 | F28: =INDEX($G$6:$N$6,1,MATCH($E28,$G$4:$N$4,0))
B29: Matéria nova (parse + currículo) | C29: Haiku 5.5 | D29: =INDEX($G$7:$N$7,1,MATCH($C29,$G$4:$N$4,0))+INDEX($G$8:$N$8,1,MATCH($C29,$G$4:$N$4,0)) | E29: Haiku 5.5 | F29: =INDEX($G$7:$N$7,1,MATCH($E29,$G$4:$N$4,0))+INDEX($G$8:$N$8,1,MATCH($E29,$G$4:$N$4,0)) | G29: 0.1 | H29: 0.02
B30: Quiz de checkpoint | C30: Haiku 5.5 | D30: =INDEX($G$9:$N$9,1,MATCH($C30,$G$4:$N$4,0)) | E30: Haiku 5.5 | F30: =INDEX($G$9:$N$9,1,MATCH($E30,$G$4:$N$4,0)) | G30: 0.3 | H30: 0.1
B31: Lote de flashcards | C31: Haiku 5.5 | D31: =INDEX($G$10:$N$10,1,MATCH($C31,$G$4:$N$4,0)) | E31: Haiku 5.5 | F31: =INDEX($G$10:$N$10,1,MATCH($E31,$G$4:$N$4,0)) | G31: 0.02 | H31: 0.02
B32: Compactação de memória | C32: Haiku 5.5 | D32: =INDEX($G$11:$N$11,1,MATCH($C32,$G$4:$N$4,0)) | E32: Haiku 5.5 | F32: =INDEX($G$11:$N$11,1,MATCH($E32,$G$4:$N$4,0)) | G32: 0.03 | H32: 0.03
B33: Roteamento proposto (PRICING_AUDIT): rota, parse, compactação e flashcards no Haiku 5.5. A tabela de roteamento põe o currículo no Sonnet 5.5, mas a 'matéria nova' a 0,1¢ só é possível no Haiku; a planilha usa Haiku e mostra a referência da auditoria ao lado.
B35: PDF (ingestão no worker)
B36: Páginas | C36: 100 | D36: PRICING_AUDIT
B37: Chunks por página | C37: 1.15 | D37: usage-audit C5
B38: Tokens de embedding por página | C38: 630 | D38: usage-audit C5
B39: Chunks por chamada de extração | C39: 5 | D39: usage-audit C5
B40: Modelo da extração | C40: Haiku 5.5 | D40: PRICING_AUDIT: Haiku 5.5 (batch quando der)
B41: Chamadas de extração | C41: =C36*C37/C39
B42: Custo da extração com desconto batch (US¢) | C42: =C41*INDEX($G$12:$N$12,1,MATCH($C$40,$G$4:$N$4,0))*(1-'Premissas'!$C$22)
B43: Custo dos embeddings (US¢) | C43: =C36*C38*'Preços API'!$C$13/1000000*100
B44: PDF completo (US¢) | C44: =C42+C43 | D44: 0.6 | E44: ← auditoria: ~0,6¢ (igual nos dois cenários)
B45: PDF completo (R$) | C45: =C44/100*'Premissas'!$C$5
...

Sheet Perfis
A1: Custo mensal de IA por perfil de uso
A2: custo = trocas × custo médio por troca (sem chamadas laterais)
B4: Perfil | C4: Trocas por mês | D4: Conservador (US$) | E4: Otimizado (US$) | F4: Conservador (R$) | G4: Otimizado (R$) | H4: Auditoria cons. (R$) | I4: Auditoria otim. (R$)
B5: Free ativado | C5: 40 | D5: =C5*'Custo por operação'!$C$22/100 | E5: =C5*'Custo por operação'!$D$22/100 | F5: =D5*'Premissas'!$C$5 | G5: =E5*'Premissas'!$C$5 | H5: 1.67 | I5: 0.77
B6: Light | C6: 80 | D6: =C6*'Custo por operação'!$C$22/100 | E6: =C6*'Custo por operação'!$D$22/100 | F6: =D6*'Premissas'!$C$5 | G6: =E6*'Premissas'!$C$5 | H6: 3.35 | I6: 1.54
B7: Normal | C7: 250 | D7: =C7*'Custo por operação'!$C$22/100 | E7: =C7*'Custo por operação'!$D$22/100 | F7: =D7*'Premissas'!$C$5 | G7: =E7*'Premissas'!$C$5 | H7: 10.46 | I7: 4.8
B8: Power | C8: 700 | D8: =C8*'Custo por operação'!$C$22/100 | E8: =C8*'Custo por operação'!$D$22/100 | F8: =D8*'Premissas'!$C$5 | G8: =E8*'Premissas'!$C$5 | H8: 29.28 | I8: 13.44
B9: Extreme, sem teto | C9: 2500 | D9: =C9*'Custo por operação'!$C$22/100 | E9: =C9*'Custo por operação'!$D$22/100 | F9: =D9*'Premissas'!$C$5 | G9: =E9*'Premissas'!$C$5 | H9: 104.56 | I9: 47.99
B10: Extreme, com o uso justo proposto | C10: → aba Planos, 'Custo de IA no teto de uso justo' (Plus / Pro)

Sheet Planos
A1: Planos propostos: receita líquida, custo de IA e margem
A2: Receita líquida = preço × (1 − deduções) − fixo do gateway. Margem = (líquida − custo de IA) ÷ líquida.
C4: Free | D4: Plus | E4: Pro | F4: Nota
B5: Preço mensal (R$) | C5: 0 | D5: 34.9 | E5: 69.9 | F5: PRICING_AUDIT
B6: Preço anual (R$) | D6: 349 | E6: 699 | F6: PRICING_AUDIT: 10× o mensal
B7: Anual: equivalente mensal (R$) | D7: =D6/12 | E7: =E6/12 | F7: Auditoria: R$ 29,08 / R$ 58,25
B8: Receita líquida mensal (R$) | C8: =IF(C5=0,0,C5*(1-'Premissas'!$C$23)-'Premissas'!$C$9) | D8: =IF(D5=0,0,D5*(1-'Premissas'!$C$23)-'Premissas'!$C$9) | E8: =IF(E5=0,0,E5*(1-'Premissas'!$C$23)-'Premissas'!$C$9) | F8: Depois de imposto, gateway (% + fixo + Billing) e reembolsos
B9: Anual: receita líquida por mês (R$) | D9: =(D6*(1-'Premissas'!$C$23)-'Premissas'!$C$9)/12 | E9: =(E6*(1-'Premissas'!$C$23)-'Premissas'!$C$9)/12 | F9: Fixo do gateway cobrado uma vez por ano
B11: Limites (o que o usuário vê)
B12: Aulas no modo completo por mês | C12: 1ª de cada trilha | D12: 40 | E12: 125 | F12: PRICING_AUDIT, limites dos planos
B13: PDFs por mês | C13: 3 | D13: 30 | E13: 100 | F13: PRICING_AUDIT
B15: Limites internos de uso justo
B16: Soft (aviso + modo padrão): créditos | C16: 180 | D16: 4000 | E16: 12500 | F16: PRICING_AUDIT. 1 crédito = US$ 0,001 de custo de lista
B17: Hard: créditos (Free) | C17: 270 | F17: PRICING_AUDIT
B18: Hard: trocas por mês no total (Plus / Pro) | D18: 2000 | E18: 4000 | F18: PRICING_AUDIT
B19: Trocas por dia | C19: 40 | D19: 150 | E19: 300 | F19: PRICING_AUDIT
B20: Soft em R$ de custo de lista | C20: =C16*'Premissas'!$C$20*'Premissas'!$C$5 | D20: =D16*'Premissas'!$C$20*'Premissas'!$C$5 | E20: =E16*'Premissas'!$C$20*'Premissas'!$C$5 | F20: Free: auditoria pede até R$ 1,00 por Free ativado (alvo) e R$ 1,50 (teto duro)
B21: Hard em R$ de custo de lista (Free) | C21: =C17*'Premissas'!$C$20*'Premissas'!$C$5
B23: Custo de IA e margem no uso esperado
B24: Trocas esperadas por mês | C24: ='Perfis'!$C$5 | D24: ='Perfis'!$C$7 | E24: ='Perfis'!$C$8 | F24: Premissa: Free = 'Free ativado', Plus = 'Normal', Pro = 'Power' (aba Perfis). A auditoria não fixa o uso esperado por plano; troque as referências se quiser outro perfil.
B25: Custo de IA, conservador (R$) | C25: =C24*'Custo por operação'!$C$22/100*'Premissas'!$C$5 | D25: =D24*'Custo por operação'!$C$22/100*'Premissas'!$C$5 | E25: =E24*'Custo por operação'!$C$22/100*'Premissas'!$C$5
B26: Custo de IA, otimizado (R$) | C26: =C24*'Custo por operação'!$D$22/100*'Premissas'!$C$5 | D26: =D24*'Custo por operação'!$D$22/100*'Premissas'!$C$5 | E26: =E24*'Custo por operação'!$D$22/100*'Premissas'!$C$5
B27: Margem bruta, conservador | D27: =IF(D8=0,0,(D8-D25)/D8) | E27: =IF(E8=0,0,(E8-E25)/E8) | F27: Auditoria: 61–62% no conservador
B28: Margem bruta, otimizado | D28: =IF(D8=0,0,(D8-D26)/D8) | E28: =IF(E8=0,0,(E8-E26)/E8) | F28: Auditoria: 77–78% no otimizado
B29: Margem bruta no mix de pagantes, conservador | D29: =(('Premissas'!$C$17*D8+'Premissas'!$C$18*E8)-('Premissas'!$C$17*D25+'Premissas'!$C$18*E25))/('Premissas'!$C$17*D8+'Premissas'!$C$18*E8) | F29: Ponderada pelo mix Plus/Pro das Premissas (um número só, na coluna Plus)
B30: Margem bruta no mix de pagantes, otimizado | D30: =(('Premissas'!$C$17*D8+'Premissas'!$C$18*E8)-('Premissas'!$C$17*D26+'Premissas'!$C$18*E26))/('Premissas'!$C$17*D8+'Premissas'!$C$18*E8)
B32: Custo de IA e margem no teto de uso justo
B33: Custo de IA no teto, conservador (R$) | C33: =C17*'Premissas'!$C$20*'Premissas'!$C$5 | D33: =(D18*'Custo por operação'!$C$22+D13*'Custo por operação'!$C$44)/100*'Premissas'!$C$5 | E33: =(E18*'Custo por operação'!$C$22+E13*'Custo por operação'!$C$44)/100*'Premissas'!$C$5 | F33: Free: teto hard em créditos. Plus/Pro: trocas do teto hard × custo da troca + PDFs do limite
B34: Custo de IA no teto, otimizado (R$) | C34: =C17*'Premissas'!$C$20*'Premissas'!$C$5 | D34: =(D18*'Custo por operação'!$D$22+D13*'Custo por operação'!$C$44)/100*'Premissas'!$C$5 | E34: =(E18*'Custo por operação'!$D$22+E13*'Custo por operação'!$C$44)/100*'Premissas'!$C$5
B35: Auditoria: 'Extreme com o uso justo' (R$) | D35: 28.71 | E35: 79.82 | F35: A auditoria não mostra como chegou a esses dois valores; não foram reproduzidos a partir dos limites.
B36: Margem no teto, conservador | D36: =(D8-D33)/D8 | E36: =(E8-E33)/E8
B37: Margem no teto, otimizado | D37: =(D8-D34)/D8 | E37: =(E8-E34)/E8
B38: Aulas completas do limite × custo da aula, conservador (R$) | D38: =D12*'Custo por operação'!$D$55/100*'Premissas'!$C$5 | E38: =E12*'Custo por operação'!$D$55/100*'Premissas'!$C$5 | F38: Informativo: o que custam as aulas no modo completo prometidas pelo plano

Sheet CAC
A1: Tetos de CAC
A2: LTV medido em lucro bruto: receita líquida × margem ÷ churn.
B4: Métrica | C4: Valor | D4: Auditoria | E4: Nota
B5: Receita líquida média por pagante (R$/mês) | C5: ='Premissas'!$C$17*'Planos'!$D$8+'Premissas'!$C$18*'Planos'!$E$8 | D5: 36.19 | E5: Mix 80% Plus / 20% Pro, já líquida
B6: Margem bruta do caso base | C6: ='Premissas'!$C$16 | D6: 0.7 | E6: Premissas
B7: Churn mensal | C7: ='Premissas'!$C$12 | D7: 0.1 | E7: Premissas
B8: LTV em lucro bruto (R$) | C8: =C5*C6/C7 | D8: 253 | E8: Igual ao CAC de break-even por pagante
B9: CAC-alvo (R$) | C9: =C8/'Premissas'!$C$14 | D9: 84 | E9: LTV ÷ LTV:CAC
B10: CAC com payback de N meses (R$) | C10: =C5*C6*'Premissas'!$C$15 | D10: 76 | E10: receita líquida × margem × meses de payback
B11: Custo máximo por cadastro (R$) | C11: =C9*'Premissas'!$C$13 | D11: 2.5 | E11: CAC-alvo × conversão. Instável até haver dados reais de conversão.
B12: Custo máximo por cadastro, critério de payback (R$) | C12: =C10*'Premissas'!$C$13
B14: Margem calculada em Planos, conservador (Plus / Pro) | C14: ='Planos'!$D$27 | D14: ='Planos'!$E$27 | E14: Referência: a aba usa a margem do caso base das Premissas, não esta
B15: Margem calculada em Planos, otimizado (Plus / Pro) | C15: ='Planos'!$D$28 | D15: ='Planos'!$E$28
B16: Margem no mix de pagantes (conservador / otimizado) | C16: ='Planos'!$D$29 | D16: ='Planos'!$D$30 | E16: Auditoria: 61–62% / 77–78%
B18: Sensibilidade do LTV (R$): margem bruta × churn mensal
B19: Margem \ churn | C19: 0.07 | D19: 0.1 | E19: 0.15
B20: 0.62 | C20: =$C$5*$B20/C$19 | D20: =$C$5*$B20/D$19 | E20: =$C$5*$B20/E$19
B21: 0.7 | C21: =$C$5*$B21/C$19 | D21: =$C$5*$B21/D$19 | E21: =$C$5*$B21/E$19
B22: 0.76 | C22: =$C$5*$B22/C$19 | D22: =$C$5*$B22/D$19 | E22: =$C$5*$B22/E$19
B23: Auditoria, para comparação:
B24: 0.62 | C24: 321 | D24: 224 | E24: 150
B25: 0.7 | C25: 362 | D25: 253 | E25: 169
B26: 0.76 | C26: 393 | D26: 275 | E26: 183

Sheet Free burn
A1: Queima do Free: os pagantes cobrem o plano grátis?
A2: Cenário da auditoria (riscos, item 1): 10 mil cadastros, 3% de conversão.
B4: Métrica | C4: Conservador | D4: Otimizado | E4: Nota
B5: Cadastros por mês | C5: 10000 | E5: PRICING_AUDIT, risco 1
B6: Ativação (% dos cadastros que usam o Mino) | C6: 0.4 | E6: PREMISSA NÃO AUDITADA. Na amostra de QA 21 de 23 contas chamaram IA; sem dado de mercado. Com 40%, o cenário conservador reproduz a frase da auditoria: o Free consome quase toda a contribuição.
B7: Conversão cadastro → pagante | C7: ='Premissas'!$C$13 | E7: Premissas
B8: Pagantes | C8: =C5*C7
B9: Free ativados | C9: =C5*C6
B10: Custo de IA por Free ativado (R$/mês) | C10: ='Perfis'!$F$5 | D10: ='Perfis'!$G$5 | E10: Aba Perfis. Auditoria: alvo R$ 1,00, teto duro R$ 1,50
B11: Queima do Free (R$/mês) | C11: =C9*C10 | D11: =C9*D10
B12: Receita líquida por pagante (R$/mês) | C12: ='CAC'!$C$5 | D12: ='CAC'!$C$5 | E12: Aba CAC
B13: Custo de IA por pagante no uso esperado (R$/mês) | C13: ='Premissas'!$C$17*'Planos'!$D$25+'Premissas'!$C$18*'Planos'!$E$25 | D13: ='Premissas'!$C$17*'Planos'!$D$26+'Premissas'!$C$18*'Planos'!$E$26 | E13: Mix Plus/Pro × custo esperado da aba Planos
B14: Contribuição dos pagantes (R$/mês) | C14: =C8*(C12-C13) | D14: =C8*(D12-D13) | E14: pagantes × (receita líquida − custo de IA)
B15: Sobra depois do Free (R$/mês) | C15: =C14-C11 | D15: =D14-D11 | E15: Negativo = o Free consome mais do que os pagantes deixam
B16: Free como % da contribuição | C16: =C11/C14 | D16: =D11/D14
B17: Ativação máxima que o Free ainda fecha | C17: =C14/(C5*C10) | D17: =D14/(C5*D10) | E17: Acima disso, a conta não fecha neste cenário
B18: Custo por Free ativado que zera a sobra (R$) | C18: =C14/C9 | D18: =D14/C9 | E18: Compare com o alvo de R$ 1,00 e o teto de R$ 1,50
